<?xml version="1.0" ?>
<!-- =================================================================================== -->
<!-- |    This document was autogenerated by xacro from robots.urdf.xacro              | -->
<!-- |    EDITING THIS FILE BY HAND IS NOT RECOMMENDED                                 | -->
<!-- =================================================================================== -->
<robot name="motoman_mh5_mh50" xmlns:xacro="http://ros.org/wiki/xacro">
  <!-- Properties -->
  <material name="yaskawa_blue">
    <color rgba="0.12941 0.14902 0.74902 1"/>
  </material>
  <!-- link list -->
  <link name="motoman_mh50_base_link">
    <inertial>
      <mass value="0.01"/>
      <origin xyz="0 0 0"/>
      <inertia ixx="0.001" ixy="0.0" ixz="0.0" iyy="0.001" iyz="0.0" izz="0.001"/>
    </inertial>
    <visual>
      <geometry>
        <mesh filename="package://motoman_mh50_support/meshes/visual/mh50_base_link.stl"/>
      </geometry>
      <material name="yaskawa_blue"/>
    </visual>
    <collision>
      <geometry>
        <mesh filename="package://motoman_mh50_support/meshes/collision/mh50_base_link.stl"/>
      </geometry>
    </collision>
  </link>
  <link name="motoman_mh50_link_1_s">
    <inertial>
      <mass value="0.01"/>
      <origin xyz="0 0 0"/>
      <inertia ixx="0.001" ixy="0.0" ixz="0.0" iyy="0.001" iyz="0.0" izz="0.001"/>
    </inertial>
    <visual>
      <geometry>
        <mesh filename="package://motoman_mh50_support/meshes/visual/mh50_link_1_s.stl"/>
      </geometry>
      <material name="yaskawa_blue"/>
    </visual>
    <collision>
      <geometry>
        <mesh filename="package://motoman_mh50_support/meshes/collision/mh50_link_1_s.stl"/>
      </geometry>
    </collision>
  </link>
  <link name="motoman_mh50_link_2_l">
    <inertial>
      <mass value="0.01"/>
      <origin xyz="0 0 0"/>
      <inertia ixx="0.001" ixy="0.0" ixz="0.0" iyy="0.001" iyz="0.0" izz="0.001"/>
    </inertial>
    <visual>
      <geometry>
        <mesh filename="package://motoman_mh50_support/meshes/visual/mh50_link_2_l.stl"/>
      </geometry>
      <material name="yaskawa_blue"/>
    </visual>
    <collision>
      <geometry>
        <mesh filename="package://motoman_mh50_support/meshes/collision/mh50_link_2_l.stl"/>
      </geometry>
    </collision>
  </link>
  <link name="motoman_mh50_link_3_u">
    <inertial>
      <mass value="0.01"/>
      <origin xyz="0 0 0"/>
      <inertia ixx="0.001" ixy="0.0" ixz="0.0" iyy="0.001" iyz="0.0" izz="0.001"/>
    </inertial>
    <visual>
      <geometry>
        <mesh filename="package://motoman_mh50_support/meshes/visual/mh50_link_3_u.stl"/>
      </geometry>
      <material name="yaskawa_blue"/>
    </visual>
    <collision>
      <geometry>
        <mesh filename="package://motoman_mh50_support/meshes/collision/mh50_link_3_u.stl"/>
      </geometry>
    </collision>
  </link>
  <link name="motoman_mh50_link_4_r">
    <inertial>
      <mass value="0.01"/>
      <origin xyz="0 0 0"/>
      <inertia ixx="0.001" ixy="0.0" ixz="0.0" iyy="0.001" iyz="0.0" izz="0.001"/>
    </inertial>
    <visual>
      <geometry>
        <mesh filename="package://motoman_mh50_support/meshes/visual/mh50_link_4_r.stl"/>
      </geometry>
      <material name="yaskawa_blue"/>
    </visual>
    <collision>
      <geometry>
        <mesh filename="package://motoman_mh50_support/meshes/collision/mh50_link_4_r.stl"/>
      </geometry>
    </collision>
  </link>
  <link name="motoman_mh50_link_5_b">
    <inertial>
      <mass value="0.01"/>
      <origin xyz="0 0 0"/>
      <inertia ixx="0.001" ixy="0.0" ixz="0.0" iyy="0.001" iyz="0.0" izz="0.001"/>
    </inertial>
    <visual>
      <geometry>
        <mesh filename="package://motoman_mh50_support/meshes/visual/mh50_link_5_b.stl"/>
      </geometry>
      <material name="yaskawa_blue"/>
    </visual>
    <collision>
      <geometry>
        <mesh filename="package://motoman_mh50_support/meshes/collision/mh50_link_5_b.stl"/>
      </geometry>
    </collision>
  </link>
  <link name="motoman_mh50_link_6_t">
    <inertial>
      <mass value="0.01"/>
      <origin xyz="0 0 0"/>
      <inertia ixx="0.001" ixy="0.0" ixz="0.0" iyy="0.001" iyz="0.0" izz="0.001"/>
    </inertial>
    <visual>
      <geometry>
        <mesh filename="package://motoman_mh50_support/meshes/visual/mh50_link_6_t.stl"/>
      </geometry>
      <material name="yaskawa_blue"/>
    </visual>
    <collision>
      <geometry>
        <mesh filename="package://motoman_mh50_support/meshes/collision/mh50_link_6_t.stl"/>
      </geometry>
    </collision>
  </link>
  <link name="motoman_mh50_tool0"/>
  <!-- end of link list -->
  <!-- joint list -->
  <joint name="motoman_mh50_joint_1_s" type="revolute">
    <parent link="motoman_mh50_base_link"/>
    <child link="motoman_mh50_link_1_s"/>
    <origin rpy="0 0 0" xyz="0 0 0.540"/>
    <axis xyz="0 0 1"/>
    <limit effort="4903.32" lower="-3.14159" upper="3.14159" velocity="3.141"/>
    <dynamics damping="0.5" friction="0.0"/>
  </joint>
  <joint name="motoman_mh50_joint_2_l" type="revolute">
    <parent link="motoman_mh50_link_1_s"/>
    <child link="motoman_mh50_link_2_l"/>
    <origin rpy="0 0 0" xyz="0.145 0 0"/>
    <axis xyz="0 1 0"/>
    <limit effort="6276.26" lower="-1.57079" upper="2.35619" velocity="3.103"/>
    <dynamics damping="0.5" friction="0.0"/>
  </joint>
  <joint name="motoman_mh50_joint_3_u" type="revolute">
    <parent link="motoman_mh50_link_2_l"/>
    <child link="motoman_mh50_link_3_u"/>
    <origin rpy="0 0 0" xyz="0 0 0.870"/>
    <axis xyz="0 -1 0"/>
    <limit effort="2745.86" lower="-1.39626" upper="3.59538" velocity="3.106"/>
    <dynamics damping="0.5" friction="0.0"/>
  </joint>
  <joint name="motoman_mh50_joint_4_r" type="revolute">
    <parent link="motoman_mh50_link_3_u"/>
    <child link="motoman_mh50_link_4_r"/>
    <origin rpy="0 0 0" xyz="1.025 0 0.210"/>
    <axis xyz="-1 0 0"/>
    <limit effort="823.76" lower="-6.28319" upper="6.28319" velocity="4.363"/>
    <dynamics damping="0.5" friction="0.0"/>
  </joint>
  <joint name="motoman_mh50_joint_5_b" type="revolute">
    <parent link="motoman_mh50_link_4_r"/>
    <child link="motoman_mh50_link_5_b"/>
    <origin rpy="0 0 0" xyz="0 0 0"/>
    <axis xyz="0 -1 0"/>
    <limit effort="706.08" lower="-2.18167" upper="2.18167" velocity="4.363"/>
    <dynamics damping="0.5" friction="0.0"/>
  </joint>
  <joint name="motoman_mh50_joint_6_t" type="revolute">
    <parent link="motoman_mh50_link_5_b"/>
    <child link="motoman_mh50_link_6_t"/>
    <origin rpy="0 0 0" xyz="0 0 0"/>
    <axis xyz="-1 0 0"/>
    <limit effort="333.43" lower="-6.2831" upper="6.2831" velocity="6.283"/>
    <dynamics damping="0.5" friction="0.0"/>
  </joint>
  <joint name="motoman_mh50_joint_6_t-tool0" type="fixed">
    <origin rpy="3.1415926 -1.570796 0" xyz="0.175 0 0"/>
    <parent link="motoman_mh50_link_6_t"/>
    <child link="motoman_mh50_tool0"/>
  </joint>
  <!-- end of joint list -->
  <!-- ROS base_link to Robot Manufacturer World Coordinates transform -->
  <link name="motoman_mh50_base"/>
  <joint name="motoman_mh50_base_link-base" type="fixed">
    <origin rpy="0 0 0" xyz="0 0 0.540"/>
    <parent link="motoman_mh50_base_link"/>
    <child link="motoman_mh50_base"/>
  </joint>
  <!-- link list -->
  <link name="motoman_mh5_base_link">
    <inertial>
      <mass value="0.01"/>
      <origin xyz="0 0 0"/>
      <inertia ixx="0.001" ixy="0.0" ixz="0.0" iyy="0.001" iyz="0.0" izz="0.001"/>
    </inertial>
    <visual>
      <origin rpy="0 0 3.14159"/>
      <geometry>
        <mesh filename="package://motoman_mh5_support/meshes/mh5/visual/MH5_BASE_AXIS.stl"/>
      </geometry>
      <material name="blue">
        <color rgba="0 0 1 1"/>
      </material>
    </visual>
    <collision>
      <origin rpy="0 0 3.14159"/>
      <geometry>
        <mesh filename="package://motoman_mh5_support/meshes/mh5/collision/MH5_BASE_AXIS.stl"/>
      </geometry>
      <material name="yellow">
        <color rgba="0 1 1 1"/>
      </material>
    </collision>
  </link>
  <link name="motoman_mh5_link_s">
    <inertial>
      <mass value="0.01"/>
      <origin xyz="0 0 0"/>
      <inertia ixx="0.001" ixy="0.0" ixz="0.0" iyy="0.001" iyz="0.0" izz="0.001"/>
    </inertial>
    <visual>
      <geometry>
        <mesh filename="package://motoman_mh5_support/meshes/mh5/visual/MH5_S_AXIS.stl"/>
      </geometry>
      <material name="silver">
        <color rgba="0.8 0.8 0.8 1"/>
      </material>
    </visual>
    <collision>
      <geometry>
        <mesh filename="package://motoman_mh5_support/meshes/mh5/collision/MH5_S_AXIS.stl"/>
      </geometry>
      <material name="yellow"/>
    </collision>
  </link>
  <link name="motoman_mh5_link_l">
    <inertial>
      <mass value="0.01"/>
      <origin xyz="0 0 0"/>
      <inertia ixx="0.001" ixy="0.0" ixz="0.0" iyy="0.001" iyz="0.0" izz="0.001"/>
    </inertial>
    <visual>
      <!-- <origin rpy="1.57 3.1416 0" xyz="0 0 0"/> -->
      <geometry>
        <mesh filename="package://motoman_mh5_support/meshes/mh5/visual/MH5_L_AXIS.stl"/>
      </geometry>
      <material name="blue"/>
    </visual>
    <collision>
      <!-- <origin rpy="1.57 3.1416 0" xyz="0 0 0"/> -->
      <geometry>
        <mesh filename="package://motoman_mh5_support/meshes/mh5/collision/MH5_L_AXIS.stl"/>
      </geometry>
      <material name="yellow"/>
    </collision>
  </link>
  <link name="motoman_mh5_link_u">
    <inertial>
      <mass value="0.01"/>
      <origin xyz="0 0 0"/>
      <inertia ixx="0.001" ixy="0.0" ixz="0.0" iyy="0.001" iyz="0.0" izz="0.001"/>
    </inertial>
    <visual>
      <!-- <origin rpy="1.57 -3.1415 0" xyz="0 0 0"/> -->
      <geometry>
        <mesh filename="package://motoman_mh5_support/meshes/mh5/visual/MH5_U_AXIS.stl"/>
      </geometry>
      <material name="blue"/>
    </visual>
    <collision>
      <!-- <origin rpy="1.57 -3.1415 0" xyz="0 0 0"/> -->
      <geometry>
        <mesh filename="package://motoman_mh5_support/meshes/mh5/collision/MH5_U_AXIS.stl"/>
      </geometry>
      <material name="yellow"/>
    </collision>
  </link>
  <link name="motoman_mh5_link_r">
    <inertial>
      <mass value="0.01"/>
      <origin xyz="0 0 0"/>
      <inertia ixx="0.001" ixy="0.0" ixz="0.0" iyy="0.001" iyz="0.0" izz="0.001"/>
    </inertial>
    <visual>
      <!-- <origin rpy="0 0 3.1416" xyz="0 0 0"/> -->
      <geometry>
        <mesh filename="package://motoman_mh5_support/meshes/mh5/visual/MH5_R_AXIS.stl"/>
      </geometry>
      <material name="silver"/>
    </visual>
    <collision>
      <!-- <origin rpy="0 0 3.1416" xyz="0 0 0"/> -->
      <geometry>
        <mesh filename="package://motoman_mh5_support/meshes/mh5/collision/MH5_R_AXIS.stl"/>
      </geometry>
      <material name="yellow"/>
    </collision>
  </link>
  <link name="motoman_mh5_link_b">
    <inertial>
      <mass value="0.01"/>
      <origin xyz="0 0 0"/>
      <inertia ixx="0.001" ixy="0.0" ixz="0.0" iyy="0.001" iyz="0.0" izz="0.001"/>
    </inertial>
    <visual>
      <!-- <origin rpy="-1.57 0 3.1416" xyz="0 0 0"/> -->
      <geometry>
        <mesh filename="package://motoman_mh5_support/meshes/mh5/visual/MH5_B_AXIS.stl"/>
      </geometry>
      <material name="blue"/>
    </visual>
    <collision>
      <!-- <origin rpy="-1.57 0 3.1416" xyz="0 0 0"/> -->
      <geometry>
        <mesh filename="package://motoman_mh5_support/meshes/mh5/collision/MH5_B_AXIS.stl"/>
      </geometry>
      <material name="yellow"/>
    </collision>
  </link>
  <link name="motoman_mh5_link_t">
    <inertial>
      <mass value="0.01"/>
      <origin xyz="0 0 0"/>
      <inertia ixx="0.001" ixy="0.0" ixz="0.0" iyy="0.001" iyz="0.0" izz="0.001"/>
    </inertial>
    <visual>
      <geometry>
        <mesh filename="package://motoman_mh5_support/meshes/mh5/visual/MH5_T_AXIS.stl"/>
      </geometry>
      <material name="silver"/>
    </visual>
    <collision>
      <geometry>
        <mesh filename="package://motoman_mh5_support/meshes/mh5/collision/MH5_T_AXIS.stl"/>
      </geometry>
      <material name="yellow"/>
    </collision>
  </link>
  <!-- end of link list -->
  <!-- joint list -->
  <joint name="motoman_mh5_joint_s" type="revolute">
    <parent link="motoman_mh5_base_link"/>
    <child link="motoman_mh5_link_s"/>
    <origin rpy="0 0 0" xyz="0 0 0.1990"/>
    <axis xyz="0 0 1"/>
    <limit effort="100" lower="-2.9671" upper="2.9671" velocity="2.96"/>
    <dynamics damping="0.5" friction="0.0"/>
  </joint>
  <joint name="motoman_mh5_joint_l" type="revolute">
    <parent link="motoman_mh5_link_s"/>
    <child link="motoman_mh5_link_l"/>
    <origin rpy="0 0 0" xyz="0.0880 0 0.1310"/>
    <axis xyz="0 1 0"/>
    <limit effort="100" lower="-1.1345" upper="2.6180" velocity="2.96"/>
    <dynamics damping="0.5" friction="0.0"/>
  </joint>
  <joint name="motoman_mh5_joint_u" type="revolute">
    <parent link="motoman_mh5_link_l"/>
    <child link="motoman_mh5_link_u"/>
    <origin rpy="0 0 0" xyz="0 0 0.3100"/>
    <axis xyz="0 -1 0"/>
    <!-- Old limits: lower="-2.3736" upper="4.4506" The new limits
           below were measured from an MH5F.  They ensure that link_r
           won't hit link_l even when joint_r is at 45 degrees.  The
           old limits were converted directly from the MH5 data sheet,
           which was clearly way off. -->
    <limit effort="100" lower="-1.0122" upper="3.2218" velocity="2.96"/>
    <dynamics damping="0.5" friction="0.0"/>
  </joint>
  <joint name="motoman_mh5_joint_r" type="revolute">
    <parent link="motoman_mh5_link_u"/>
    <child link="motoman_mh5_link_r"/>
    <origin rpy="0 0 0" xyz="0.0715 0 0.0399"/>
    <axis xyz="-1 0 0"/>
    <limit effort="100" lower="-3.3161" upper="3.3161" velocity="3.48"/>
  </joint>
  <joint name="motoman_mh5_joint_b" type="revolute">
    <parent link="motoman_mh5_link_r"/>
    <child link="motoman_mh5_link_b"/>
    <origin rpy="0 0 0" xyz="0.2335 0 0"/>
    <axis xyz="0 -1 0"/>
    <limit effort="100" lower="-2.1817" upper="2.1817" velocity="3.48"/>
    <dynamics damping="0.5" friction="0.0"/>
  </joint>
  <joint name="motoman_mh5_joint_t" type="revolute">
    <parent link="motoman_mh5_link_b"/>
    <child link="motoman_mh5_link_t"/>
    <origin rpy="0 0 0" xyz="0.0865 0 0"/>
    <axis xyz="-1 0 0"/>
    <limit effort="100" lower="-6.2831" upper="6.2831" velocity="6.97"/>
    <dynamics damping="0.5" friction="0.0"/>
  </joint>
  <!-- end of joint list -->
  <!-- Used for fixing robot to Gazebo -->
  <link name="world"/>
  <!-- Dummy Link -->
  <link name="dummy_link"/>
  <joint name="world_joint" type="fixed">
    <parent link="world"/>
    <child link="dummy_link"/>
    <origin rpy="0 0 0" xyz="0 0 0"/>
    <axis xyz="0 0 1"/>
  </joint>
  <!-- motoman_mh50 -->
  <joint name="motoman_mh50_joint_dummy" type="fixed">
    <parent link="dummy_link"/>
    <child link="motoman_mh50_base_link"/>
    <origin rpy="0 0 0" xyz="1 0 0.1"/>
  </joint>
  <!-- motoman_mh5 -->
  <joint name="motoman_mh5_joint_dummy" type="fixed">
    <parent link="dummy_link"/>
    <child link="motoman_mh5_base_link"/>
    <origin rpy="0 0 0" xyz="-1.5 0 0.1"/>
  </joint>
  <!-- joint between arm_ee_link and vacuum_gripper_link 
      gripper mesh from https://onrobot.com/en/downloads-->
  <joint name="vacuum_gripper_base_joint" type="fixed">
    <origin rpy="-1.57 0 0" xyz="0.0 0.0 0.0"/>
    <parent link="motoman_mh50_tool0"/>
    <child link="vacuum_gripper_frame"/>
  </joint>
  <link name="vacuum_gripper_frame"/>
  <joint name="gripper_to_palm" type="fixed">
    <parent link="vacuum_gripper_frame"/>
    <child link="vacuum_gripper_body"/>
    <origin rpy="0 0 0" xyz="0.0 0.0 0.0"/>
  </joint>
  <link name="vacuum_gripper_body">
    <inertial>
      <mass value="0.01"/>
      <origin xyz="0 0 0"/>
      <inertia ixx="0.001" ixy="0.0" ixz="0.0" iyy="0.001" iyz="0.0" izz="0.001"/>
    </inertial>
    <visual>
      <origin rpy="0 0 0" xyz="0 0 0"/>
      <geometry>
        <mesh filename="package://motoman_move_glass/mesh/pr10.stl" scale="0.001 0.001 0.001"/>
      </geometry>
      <material name="silver">
        <color rgba="0.8 0.8 0.8 1"/>
      </material>
    </visual>
    <collision>
      <origin rpy="0 0 0" xyz="0.0 0.0 0"/>
      <geometry>
        <box size="0.13 0.14 0.071"/>
      </geometry>
    </collision>
  </link>
  <joint name="gripper_to_tcp" type="fixed">
    <parent link="vacuum_gripper_frame"/>
    <child link="vacuum_gripper_top"/>
    <origin rpy="3.14159 0 0" xyz=" 0 -0.1 0.0"/>
  </joint>
  <link name="vacuum_gripper_top">
    <inertial>
      <mass value="0.01"/>
      <origin xyz="0 0 0"/>
      <inertia ixx="0.001" ixy="0.0" ixz="0.0" iyy="0.001" iyz="0.0" izz="0.001"/>
    </inertial>
    <visual>
      <geometry>
        <box size="0.01 0.01 0.01"/>
      </geometry>
      <material name="white">
        <color rgba="1 1 1 0.5"/>
      </material>
    </visual>
    <collision>
      <geometry>
        <box size="0.01 0.01 0.01"/>
      </geometry>
    </collision>
  </link>
  <joint name="glass_joint" type="fixed">
    <origin rpy="1.57 0 3.14159" xyz="0 -0.02 0"/>
    <parent link="vacuum_gripper_top"/>
    <child link="glass_link"/>
  </joint>
  <link name="glass_link">
    <inertial>
      <mass value="0.01"/>
      <origin xyz="0 0 0"/>
      <inertia ixx="0.001" ixy="0.0" ixz="0.0" iyy="0.001" iyz="0.0" izz="0.001"/>
    </inertial>
    <visual>
      <geometry>
        <box size="0.4 1 0.005"/>
      </geometry>
      <material name="Cyan">
        <color rgba="0 1.0 1.0 1.0"/>
      </material>
    </visual>
    <collision>
      <geometry>
        <box size="0.4 1 0.005"/>
      </geometry>
    </collision>
  </link>
  <gazebo reference="motoman_mh50_base_link">
    <gravity>true</gravity>
    <self_collide>false</self_collide>
    <material value="Gazebo/Grey"/>
  </gazebo>
  <gazebo reference="motoman_mh50_link_1_s">
    <gravity>true</gravity>
    <self_collide>false</self_collide>
    <material value="Gazebo/Black"/>
  </gazebo>
  <gazebo reference="motoman_mh50_link_2_l">
    <gravity>true</gravity>
    <self_collide>false</self_collide>
    <material value="Gazebo/Black"/>
  </gazebo>
  <gazebo reference="motoman_mh50_link_3_u">
    <gravity>true</gravity>
    <self_collide>false</self_collide>
    <material value="Gazebo/Grey"/>
  </gazebo>
  <gazebo reference="motoman_mh50_link_4_r">
    <gravity>true</gravity>
    <self_collide>false</self_collide>
    <material value="Gazebo/Blue"/>
  </gazebo>
  <gazebo reference="motoman_mh50_link_5_b">
    <gravity>true</gravity>
    <self_collide>false</self_collide>
    <material value="Gazebo/Blue"/>
  </gazebo>
  <gazebo reference="motoman_mh50_link_6_t">
    <gravity>true</gravity>
    <self_collide>false</self_collide>
    <material value="Gazebo/Blue"/>
  </gazebo>
  <gazebo reference="motoman_mh50_tool0">
    <gravity>true</gravity>
    <self_collide>false</self_collide>
    <material value="Gazebo/Blue"/>
  </gazebo>
  <gazebo reference="motoman_mh5_base_link">
    <gravity>true</gravity>
    <self_collide>false</self_collide>
    <material value="Gazebo/Blue"/>
  </gazebo>
  <gazebo reference="motoman_mh5_link_s">
    <gravity>true</gravity>
    <self_collide>false</self_collide>
    <material value="Gazebo/Blue"/>
  </gazebo>
  <gazebo reference="motoman_mh5_link_l">
    <gravity>true</gravity>
    <self_collide>false</self_collide>
    <material value="Gazebo/Blue"/>
  </gazebo>
  <gazebo reference="motoman_mh5_link_u">
    <gravity>true</gravity>
    <self_collide>false</self_collide>
    <material value="Gazebo/Blue"/>
  </gazebo>
  <gazebo reference="motoman_mh5_link_r">
    <gravity>true</gravity>
    <self_collide>false</self_collide>
    <material value="Gazebo/Blue"/>
  </gazebo>
  <gazebo reference="motoman_mh5_link_b">
    <gravity>true</gravity>
    <self_collide>false</self_collide>
    <material value="Gazebo/Blue"/>
  </gazebo>
  <gazebo reference="motoman_mh5_link_t">
    <gravity>true</gravity>
    <self_collide>false</self_collide>
    <material value="Gazebo/Blue"/>
  </gazebo>
  <transmission name="motoman_mh50_joint_1_s_trans">
    <type>transmission_interface/SimpleTransmission</type>
    <joint name="motoman_mh50_joint_1_s">
      <!--<hardwareInterface>hardware_interface/EffortJointInterface</hardwareInterface>-->
      <hardwareInterface>hardware_interface/PositionJointInterface</hardwareInterface>
    </joint>
    <actuator name="motoman_mh50_joint_1_s_motor">
      <hardwareInterface>hardware_interface/EffortJointInterface</hardwareInterface>
      <mechanicalReduction>1</mechanicalReduction>
    </actuator>
  </transmission>
  <transmission name="motoman_mh50_joint_2_l_trans">
    <type>transmission_interface/SimpleTransmission</type>
    <joint name="motoman_mh50_joint_2_l">
      <!--<hardwareInterface>hardware_interface/EffortJointInterface</hardwareInterface>-->
      <hardwareInterface>hardware_interface/PositionJointInterface</hardwareInterface>
    </joint>
    <actuator name="motoman_mh50_joint_2_l_motor">
      <hardwareInterface>hardware_interface/EffortJointInterface</hardwareInterface>
      <mechanicalReduction>1</mechanicalReduction>
    </actuator>
  </transmission>
  <transmission name="motoman_mh50_joint_3_u_trans">
    <type>transmission_interface/SimpleTransmission</type>
    <joint name="motoman_mh50_joint_3_u">
      <hardwareInterface>hardware_interface/PositionJointInterface</hardwareInterface>
      <!--hardwareInterface>hardware_interface/VelocityJointInterface</hardwareInterface>
      <hardwareInterface>EffortJointInterface</hardwareInterface-->
    </joint>
    <actuator name="motoman_mh50_joint_3_u_motor">
      <hardwareInterface>hardware_interface/EffortJointInterface</hardwareInterface>
      <mechanicalReduction>1</mechanicalReduction>
    </actuator>
  </transmission>
  <transmission name="motoman_mh50_joint_4_r_trans">
    <type>transmission_interface/SimpleTransmission</type>
    <joint name="motoman_mh50_joint_4_r">
      <hardwareInterface>hardware_interface/PositionJointInterface</hardwareInterface>
      <!--hardwareInterface>hardware_interface/VelocityJointInterface</hardwareInterface>
      <hardwareInterface>EffortJointInterface</hardwareInterface-->
    </joint>
    <actuator name="motoman_mh50_joint_4_r_motor">
      <hardwareInterface>hardware_interface/EffortJointInterface</hardwareInterface>
      <mechanicalReduction>1</mechanicalReduction>
    </actuator>
  </transmission>
  <transmission name="motoman_mh50_joint_5_b_trans">
    <type>transmission_interface/SimpleTransmission</type>
    <joint name="motoman_mh50_joint_5_b">
      <hardwareInterface>hardware_interface/PositionJointInterface</hardwareInterface>
      <!--hardwareInterface>hardware_interface/VelocityJointInterface</hardwareInterface>
      <hardwareInterface>EffortJointInterface</hardwareInterface-->
    </joint>
    <actuator name="motoman_mh50_joint_5_b_motor">
      <hardwareInterface>hardware_interface/EffortJointInterface</hardwareInterface>
      <mechanicalReduction>1</mechanicalReduction>
    </actuator>
  </transmission>
  <transmission name="motoman_mh50_joint_6_t_trans">
    <type>transmission_interface/SimpleTransmission</type>
    <joint name="motoman_mh50_joint_6_t">
      <hardwareInterface>hardware_interface/PositionJointInterface</hardwareInterface>
      <!--hardwareInterface>hardware_interface/VelocityJointInterface</hardwareInterface>
      <hardwareInterface>EffortJointInterface</hardwareInterface-->
    </joint>
    <actuator name="motoman_mh50_joint_6_t_motor">
      <hardwareInterface>hardware_interface/EffortJointInterface</hardwareInterface>
      <mechanicalReduction>1</mechanicalReduction>
    </actuator>
  </transmission>
  <transmission name="motoman_mh5_joint_s_trans">
    <type>transmission_interface/SimpleTransmission</type>
    <joint name="motoman_mh5_joint_s">
      <hardwareInterface>hardware_interface/PositionJointInterface</hardwareInterface>
      <!--hardwareInterface>hardware_interface/VelocityJointInterface</hardwareInterface>
      <hardwareInterface>EffortJointInterface</hardwareInterface-->
    </joint>
    <actuator name="motoman_mh5_joint_s_motor">
      <hardwareInterface>hardware_interface/EffortJointInterface</hardwareInterface>
      <mechanicalReduction>1</mechanicalReduction>
    </actuator>
  </transmission>
  <transmission name="motoman_mh5_joint_l_trans">
    <type>transmission_interface/SimpleTransmission</type>
    <joint name="motoman_mh5_joint_l">
      <hardwareInterface>hardware_interface/PositionJointInterface</hardwareInterface>
      <!--hardwareInterface>hardware_interface/VelocityJointInterface</hardwareInterface>
      <hardwareInterface>EffortJointInterface</hardwareInterface-->
    </joint>
    <actuator name="motoman_mh5_joint_l_motor">
      <hardwareInterface>hardware_interface/EffortJointInterface</hardwareInterface>
      <mechanicalReduction>1</mechanicalReduction>
    </actuator>
  </transmission>
  <transmission name="motoman_mh5_joint_u_trans">
    <type>transmission_interface/SimpleTransmission</type>
    <joint name="motoman_mh5_joint_u">
      <hardwareInterface>hardware_interface/PositionJointInterface</hardwareInterface>
      <!--hardwareInterface>hardware_interface/VelocityJointInterface</hardwareInterface>
      <hardwareInterface>EffortJointInterface</hardwareInterface-->
    </joint>
    <actuator name="motoman_mh5_joint_u_motor">
      <hardwareInterface>hardware_interface/EffortJointInterface</hardwareInterface>
      <mechanicalReduction>1</mechanicalReduction>
    </actuator>
  </transmission>
  <transmission name="motoman_mh5_joint_r_trans">
    <type>transmission_interface/SimpleTransmission</type>
    <joint name="motoman_mh5_joint_r">
      <hardwareInterface>hardware_interface/PositionJointInterface</hardwareInterface>
      <!--hardwareInterface>hardware_interface/VelocityJointInterface</hardwareInterface>
      <hardwareInterface>EffortJointInterface</hardwareInterface-->
    </joint>
    <actuator name="motoman_mh5_joint_r_motor">
      <hardwareInterface>hardware_interface/EffortJointInterface</hardwareInterface>
      <mechanicalReduction>1</mechanicalReduction>
    </actuator>
  </transmission>
  <transmission name="motoman_mh5_joint_b_trans">
    <type>transmission_interface/SimpleTransmission</type>
    <joint name="motoman_mh5_joint_b">
      <hardwareInterface>hardware_interface/PositionJointInterface</hardwareInterface>
      <!--hardwareInterface>hardware_interface/VelocityJointInterface</hardwareInterface>
      <hardwareInterface>EffortJointInterface</hardwareInterface-->
    </joint>
    <actuator name="motoman_mh5_joint_b_motor">
      <hardwareInterface>hardware_interface/EffortJointInterface</hardwareInterface>
      <mechanicalReduction>1</mechanicalReduction>
    </actuator>
  </transmission>
  <transmission name="motoman_mh5_joint_t_trans">
    <type>transmission_interface/SimpleTransmission</type>
    <joint name="motoman_mh5_joint_t">
      <hardwareInterface>hardware_interface/PositionJointInterface</hardwareInterface>
      <!--hardwareInterface>hardware_interface/VelocityJointInterface</hardwareInterface>
      <hardwareInterface>EffortJointInterface</hardwareInterface-->
    </joint>
    <actuator name="motoman_mh5_joint_t_motor">
      <hardwareInterface>hardware_interface/EffortJointInterface</hardwareInterface>
      <mechanicalReduction>1</mechanicalReduction>
    </actuator>
  </transmission>
  <!--gazebo>
      <plugin name="ros_control" filename="libhwi_switch_gazebo_ros_control.so">
        <robotNamespace>motoman_mh5_mh50</robotNamespace>
        <filterJointsParam>joint_names</filterJointsParam>
      </plugin>
  </gazebo-->
  <gazebo>
    <static>false</static>

    <plugin name="gazebo_ros_control" filename="libgazebo_ros_control.so">
      <robotNamespace>/motoman_mh5_mh50</robotNamespace>
        <filterJointsParam>joint_names</filterJointsParam>
      <robotSimType>gazebo_ros_control/DefaultRobotHWSim</robotSimType>
      <legacyModeNS>true</legacyModeNS>
    </plugin>
</gazebo>
</robot>

